<?xml version="1.0" ?>
<!-- =================================================================================== -->
<!-- |    This document was autogenerated by xacro from panda.urdf.xacro               | -->
<!-- |    EDITING THIS FILE BY HAND IS NOT RECOMMENDED                                 | -->
<!-- =================================================================================== -->
<robot name="panda">
  <!-- sub-link defining detailed ../meshes/panda for collision with environment -->
  <link name="panda_link0">
    <visual>
      <geometry>
        <mesh filename="../meshes/panda/link0.dae"/>
      </geometry>
    </visual>
  </link>
  <link name="panda_link1">
    <visual>
      <geometry>
        <mesh filename="../meshes/panda/link1.dae"/>
      </geometry>
    </visual>
  </link>
  <!-- sub-link defining coarse geometries of real robot's internal self-collision -->
  <!-- fixed joint between both sub-links -->
  <joint name="panda_joint1" type="revolute">
    <origin rpy="0 0 0" xyz="0 0 0.333"/>
    <parent link="panda_link0"/>
    <child link="panda_link1"/>
    <axis xyz="0 0 1"/>
    <limit effort="87.0" lower="-2.8973" upper="2.8973" velocity="2.175"/>
    <safety_controller k_position="100.0" k_velocity="40.0" soft_lower_limit="-2.8973" soft_upper_limit="2.8973"/>
  </joint>
  <!-- sub-link defining detailed ../meshes/panda for collision with environment -->
  <link name="panda_link2">
    <visual>
      <geometry>
        <mesh filename="../meshes/panda/link2.dae"/>
      </geometry>
    </visual>
  </link>
  <!-- sub-link defining coarse geometries of real robot's internal self-collision -->
  <joint name="panda_joint2" type="revolute">
    <origin rpy="-1.5707963267948966 0 0" xyz="0 0 0"/>
    <parent link="panda_link1"/>
    <child link="panda_link2"/>
    <axis xyz="0 0 1"/>
    <limit effort="87.0" lower="-1.7628" upper="1.7628" velocity="2.175"/>
    <safety_controller k_position="100.0" k_velocity="40.0" soft_lower_limit="-1.7628" soft_upper_limit="1.7628"/>
  </joint>
  <!-- sub-link defining detailed ../meshes/panda for collision with environment -->
  <link name="panda_link3">
    <visual>
      <geometry>
        <mesh filename="../meshes/panda/link3.dae"/>
      </geometry>
    </visual>
  </link>
  <!-- sub-link defining coarse geometries of real robot's internal self-collision -->
  <joint name="panda_joint3" type="revolute">
    <origin rpy="1.5707963267948966 0 0" xyz="0 -0.316 0"/>
    <parent link="panda_link2"/>
    <child link="panda_link3"/>
    <axis xyz="0 0 1"/>
    <limit effort="87.0" lower="-2.8973" upper="2.8973" velocity="2.175"/>
    <safety_controller k_position="100.0" k_velocity="40.0" soft_lower_limit="-2.8973" soft_upper_limit="2.8973"/>
  </joint>
  <!-- sub-link defining detailed ../meshes/panda for collision with environment -->
  <link name="panda_link4">
    <visual>
      <geometry>
        <mesh filename="../meshes/panda/link4.dae"/>
      </geometry>
    </visual>
  </link>
  <!-- sub-link defining coarse geometries of real robot's internal self-collision -->
  <joint name="panda_joint4" type="revolute">
    <origin rpy="1.5707963267948966 0 0" xyz="0.0825 0 0"/>
    <parent link="panda_link3"/>
    <child link="panda_link4"/>
    <axis xyz="0 0 1"/>
    <limit effort="87.0" lower="-3.0718" upper="-0.0698" velocity="2.175"/>
    <safety_controller k_position="100.0" k_velocity="40.0" soft_lower_limit="-3.0718" soft_upper_limit="-0.0698"/>
  </joint>
  <!-- sub-link defining detailed ../meshes/panda for collision with environment -->
  <link name="panda_link5">
    <visual>
      <geometry>
        <mesh filename="../meshes/panda/link5.dae"/>
      </geometry>
    </visual>
  </link>
  <!-- sub-link defining coarse geometries of real robot's internal self-collision -->
  <joint name="panda_joint5" type="revolute">
    <origin rpy="-1.5707963267948966 0 0" xyz="-0.0825 0.384 0"/>
    <parent link="panda_link4"/>
    <child link="panda_link5"/>
    <axis xyz="0 0 1"/>
    <limit effort="12.0" lower="-2.8973" upper="2.8973" velocity="2.61"/>
    <safety_controller k_position="100.0" k_velocity="40.0" soft_lower_limit="-2.8973" soft_upper_limit="2.8973"/>
  </joint>
  <!-- sub-link defining detailed ../meshes/panda for collision with environment -->
  <link name="panda_link6">
    <visual>
      <geometry>
        <mesh filename="../meshes/panda/link6.dae"/>
      </geometry>
    </visual>
  </link>
  <!-- sub-link defining coarse geometries of real robot's internal self-collision -->
  <joint name="panda_joint6" type="revolute">
    <origin rpy="1.5707963267948966 0 0" xyz="0 0 0"/>
    <parent link="panda_link5"/>
    <child link="panda_link6"/>
    <axis xyz="0 0 1"/>
    <limit effort="12.0" lower="-0.0175" upper="3.7525" velocity="2.61"/>
    <safety_controller k_position="100.0" k_velocity="40.0" soft_lower_limit="-0.0175" soft_upper_limit="3.7525"/>
  </joint>
  <!-- sub-link defining detailed ../meshes/panda for collision with environment -->
  <link name="panda_link7">
    <visual>
      <geometry>
        <mesh filename="../meshes/panda/link7.dae"/>
      </geometry>
    </visual>
  </link>
  <!-- sub-link defining coarse geometries of real robot's internal self-collision -->
  <joint name="panda_joint7" type="revolute">
    <origin rpy="1.5707963267948966 0 0" xyz="0.088 0 0"/>
    <parent link="panda_link6"/>
    <child link="panda_link7"/>
    <axis xyz="0 0 1"/>
    <limit effort="12.0" lower="-2.8973" upper="2.8973" velocity="2.61"/>
    <safety_controller k_position="100.0" k_velocity="40.0" soft_lower_limit="-2.8973" soft_upper_limit="2.8973"/>
  </joint>
  <link name="panda_link8"/>
  <joint name="panda_joint8" type="fixed">
    <origin rpy="0 0 0" xyz="0 0 0.107"/>
    <parent link="panda_link7"/>
    <child link="panda_link8"/>
  </joint>
  <joint name="panda_hand_joint" type="fixed">
    <parent link="panda_link8"/>
    <child link="panda_hand"/>
    <origin rpy="0 0 -0.7853981633974483" xyz="0 0 0"/>
  </joint>
  <!-- sub-link defining detailed ../meshes/panda for collision with environment -->
  <link name="panda_hand">
    <visual>
      <geometry>
        <mesh filename="../meshes/panda/hand.dae"/>
      </geometry>
    </visual>
  </link>
  <link name="panda_hand_tcp"/>
  <joint name="panda_hand_tcp_joint" type="fixed">
    <origin rpy="0 0 0" xyz="0 0 0.1034"/>
    <parent link="panda_hand"/>
    <child link="panda_hand_tcp"/>
  </joint>
  <link name="ball_link">
    <visual>
      <material name="red">
        <color rgba="1 0 0 1"/>
      </material>

      <geometry>
        <sphere radius="0.005"/>
      </geometry>
    </visual>
  </link>

  <joint name="ball_joint" type="fixed">
    <origin rpy="0.0 0.0 0.0" xyz="7.773732033005863e-05 -4.214022515884392e-05 0.030128297908475325" />
    <parent link="panda_hand_tcp"/>
    <child link="ball_link"/>
  </joint>
  <link name="panda_leftfinger">
    <visual>
      <geometry>
        <mesh filename="../meshes/panda/finger.dae"/>
      </geometry>
    </visual>
  </link>
  <link name="panda_rightfinger">
    <visual>
      <origin rpy="0 0 3.141592653589793" xyz="0 0 0"/>
      <geometry>
        <mesh filename="../meshes/panda/finger.dae"/>
      </geometry>
    </visual>
  </link>
  <joint name="panda_finger_joint1" type="fixed">
    <parent link="panda_hand"/>
    <child link="panda_leftfinger"/>
    <origin rpy="0 0 0" xyz="0 0 0.0584"/>
  </joint>
  <joint name="panda_finger_joint2" type="fixed">
    <parent link="panda_hand"/>
    <child link="panda_rightfinger"/>
    <origin rpy="0 0 0" xyz="0 0 0.0584"/>
  </joint>
</robot>

