<?xml version='1.0' encoding='utf-8'?>
<robot name="panda">
  
  <link name="panda_link0">
    <visual>
      <geometry>
        <mesh filename="package://franka_description/meshes/visual/link0.dae" />
      </geometry>
    </visual>
    <collision>
      <geometry>
        <mesh filename="package://franka_description/meshes/collision/link0.stl" />
      </geometry>
    </collision>
  </link>
  
  <link name="panda_link0_sc">
    <collision>
      <origin rpy="0 1.5707963267948966 0" xyz="-0.075 0 0.06" />
      <geometry>
        <cylinder length="0.03" radius="0.09" />
      </geometry>
    </collision>
    <collision>
      <origin xyz="-0.06 0 0.06" />
      <geometry>
        <sphere radius="0.09" />
      </geometry>
    </collision>
    <collision>
      <origin xyz="-0.09 0 0.06" />
      <geometry>
        <sphere radius="0.09" />
      </geometry>
    </collision>
  </link>
  
  <joint name="panda_link0_sc_joint" type="fixed">
    <origin rpy="0 0 0" />
    <parent link="panda_link0" />
    <child link="panda_link0_sc" />
  </joint>
  
  <link name="panda_link1">
    <visual>
      <geometry>
        <mesh filename="package://franka_description/meshes/visual/link1.dae" />
      </geometry>
    </visual>
    <collision>
      <geometry>
        <mesh filename="package://franka_description/meshes/collision/link1.stl" />
      </geometry>
    </collision>
  </link>
  
  <link name="panda_link1_sc">
    <collision>
      <origin rpy="0 0 0" xyz="0 0 -0.1915" />
      <geometry>
        <cylinder length="0.283" radius="0.09" />
      </geometry>
    </collision>
    <collision>
      <origin xyz="0 0 -0.05000000000000002" />
      <geometry>
        <sphere radius="0.09" />
      </geometry>
    </collision>
    <collision>
      <origin xyz="0 0 -0.33299999999999996" />
      <geometry>
        <sphere radius="0.09" />
      </geometry>
    </collision>
  </link>
  
  <joint name="panda_link1_sc_joint" type="fixed">
    <origin rpy="0 0 0" />
    <parent link="panda_link1" />
    <child link="panda_link1_sc" />
  </joint>
  <joint name="panda_joint1" type="revolute">
    <origin rpy="8.689992944594739e-17 -6.332846994001553e-16 5.614519598369499e-16" xyz="1.1531650953807166e-15 -2.253583251838131e-15 0.3330000000000007" />
    <parent link="panda_link0" />
    <child link="panda_link1" />
    <axis xyz="0 0 1" />
    <limit effort="87.0" lower="-2.8973" upper="2.8973" velocity="2.175" />
    <safety_controller k_position="100.0" k_velocity="40.0" soft_lower_limit="-2.8973" soft_upper_limit="2.8973" />
    <dynamics D="1" K="7000" damping="0.003" friction="0.0" mu_coulomb="0" mu_viscous="16" />
  </joint>
  
  <link name="panda_link2">
    <visual>
      <geometry>
        <mesh filename="package://franka_description/meshes/visual/link2.dae" />
      </geometry>
    </visual>
    <collision>
      <geometry>
        <mesh filename="package://franka_description/meshes/collision/link2.stl" />
      </geometry>
    </collision>
  </link>
  
  <link name="panda_link2_sc">
    <collision>
      <origin rpy="0 0 0" xyz="0 0 0" />
      <geometry>
        <cylinder length="0.12" radius="0.09" />
      </geometry>
    </collision>
    <collision>
      <origin xyz="0 0 0.06" />
      <geometry>
        <sphere radius="0.09" />
      </geometry>
    </collision>
    <collision>
      <origin xyz="0 0 -0.06" />
      <geometry>
        <sphere radius="0.09" />
      </geometry>
    </collision>
  </link>
  
  <joint name="panda_link2_sc_joint" type="fixed">
    <origin rpy="0 0 0" />
    <parent link="panda_link2" />
    <child link="panda_link2_sc" />
  </joint>
  <joint name="panda_joint2" type="revolute">
    <origin rpy="-1.5721416508473902 0.0009573864347817382 3.823257403467354e-10" xyz="5.696995638674702e-05 -0.0002634498797404347 6.917207119953859e-16" />
    <parent link="panda_link1" />
    <child link="panda_link2" />
    <axis xyz="0 0 1" />
    <limit effort="87.0" lower="-1.7628" upper="1.7628" velocity="2.175" />
    <safety_controller k_position="100.0" k_velocity="40.0" soft_lower_limit="-1.7628" soft_upper_limit="1.7628" />
    <dynamics D="1" K="7000" damping="0.003" friction="0.0" mu_coulomb="0" mu_viscous="16" />
  </joint>
  
  <link name="panda_link3">
    <visual>
      <geometry>
        <mesh filename="package://franka_description/meshes/visual/link3.dae" />
      </geometry>
    </visual>
    <collision>
      <geometry>
        <mesh filename="package://franka_description/meshes/collision/link3.stl" />
      </geometry>
    </collision>
  </link>
  
  <link name="panda_link3_sc">
    <collision>
      <origin rpy="0 0 0" xyz="0 0 -0.145" />
      <geometry>
        <cylinder length="0.15" radius="0.09" />
      </geometry>
    </collision>
    <collision>
      <origin xyz="0 0 -0.06999999999999999" />
      <geometry>
        <sphere radius="0.09" />
      </geometry>
    </collision>
    <collision>
      <origin xyz="0 0 -0.21999999999999997" />
      <geometry>
        <sphere radius="0.09" />
      </geometry>
    </collision>
  </link>
  
  <joint name="panda_link3_sc_joint" type="fixed">
    <origin rpy="0 0 0" />
    <parent link="panda_link3" />
    <child link="panda_link3_sc" />
  </joint>
  <joint name="panda_joint3" type="revolute">
    <origin rpy="1.5724328190952739 -0.0006556894920200575 0.0010361370595500133" xyz="-0.0002565789851127319 -0.3147667827649975 -0.0002634497074263931" />
    <parent link="panda_link2" />
    <child link="panda_link3" />
    <axis xyz="0 0 1" />
    <limit effort="87.0" lower="-2.8973" upper="2.8973" velocity="2.175" />
    <safety_controller k_position="100.0" k_velocity="40.0" soft_lower_limit="-2.8973" soft_upper_limit="2.8973" />
    <dynamics D="1" K="7000" damping="0.003" friction="0.0" mu_coulomb="0" mu_viscous="16" />
  </joint>
  
  <link name="panda_link4">
    <visual>
      <geometry>
        <mesh filename="package://franka_description/meshes/visual/link4.dae" />
      </geometry>
    </visual>
    <collision>
      <geometry>
        <mesh filename="package://franka_description/meshes/collision/link4.stl" />
      </geometry>
    </collision>
  </link>
  
  <link name="panda_link4_sc">
    <collision>
      <origin rpy="0 0 0" xyz="0 0 0" />
      <geometry>
        <cylinder length="0.12" radius="0.09" />
      </geometry>
    </collision>
    <collision>
      <origin xyz="0 0 0.06" />
      <geometry>
        <sphere radius="0.09" />
      </geometry>
    </collision>
    <collision>
      <origin xyz="0 0 -0.06" />
      <geometry>
        <sphere radius="0.09" />
      </geometry>
    </collision>
  </link>
  
  <joint name="panda_link4_sc_joint" type="fixed">
    <origin rpy="0 0 0" />
    <parent link="panda_link4" />
    <child link="panda_link4_sc" />
  </joint>
  <joint name="panda_joint4" type="revolute">
    <origin rpy="1.5722982502162635 0.00995312287323032 0.0007071007819809249" xyz="0.08166443899594983 -0.0006500261150543214 -0.0012330556900883628" />
    <parent link="panda_link3" />
    <child link="panda_link4" />
    <axis xyz="0 0 1" />
    <limit effort="87.0" lower="-3.0718" upper="-0.0698" velocity="2.175" />
    <safety_controller k_position="100.0" k_velocity="40.0" soft_lower_limit="-3.0718" soft_upper_limit="-0.0698" />
    <dynamics D="1" K="7000" damping="0.003" friction="0.0" mu_coulomb="0" mu_viscous="16" />
  </joint>
  
  <link name="panda_link5">
    <visual>
      <geometry>
        <mesh filename="package://franka_description/meshes/visual/link5.dae" />
      </geometry>
    </visual>
    <collision>
      <geometry>
        <mesh filename="package://franka_description/meshes/collision/link5.stl" />
      </geometry>
    </collision>
  </link>
  
  <link name="panda_link5_sc">
    <collision>
      <origin rpy="0 0 0" xyz="0 0 -0.26" />
      <geometry>
        <cylinder length="0.1" radius="0.09" />
      </geometry>
    </collision>
    <collision>
      <origin xyz="0 0 -0.21000000000000002" />
      <geometry>
        <sphere radius="0.09" />
      </geometry>
    </collision>
    <collision>
      <origin xyz="0 0 -0.31" />
      <geometry>
        <sphere radius="0.09" />
      </geometry>
    </collision>
    <collision>
      <origin rpy="0 0 0.08" xyz="0 0.08 -0.13" />
      <geometry>
        <cylinder length="0.14" radius="0.055" />
      </geometry>
    </collision>
    <collision>
      <origin xyz="0 0.08 -0.06" />
      <geometry>
        <sphere radius="0.055" />
      </geometry>
    </collision>
    <collision>
      <origin xyz="0 0.08 -0.2" />
      <geometry>
        <sphere radius="0.055" />
      </geometry>
    </collision>
  </link>
  
  <joint name="panda_link5_sc_joint" type="fixed">
    <origin rpy="0 0 0" />
    <parent link="panda_link5" />
    <child link="panda_link5_sc" />
  </joint>
  <joint name="panda_joint5" type="revolute">
    <origin rpy="-1.570646370598403 0.005749460637451966 -0.00995328920600513" xyz="-0.07758573855528328 0.3833417065524507 0.0006512790375435742" />
    <parent link="panda_link4" />
    <child link="panda_link5" />
    <axis xyz="0 0 1" />
    <limit effort="12.0" lower="-2.8973" upper="2.8973" velocity="2.61" />
    <safety_controller k_position="100.0" k_velocity="40.0" soft_lower_limit="-2.8973" soft_upper_limit="2.8973" />
    <dynamics D="1" K="7000" damping="0.003" friction="0.0" mu_coulomb="0" mu_viscous="16" />
  </joint>
  
  <link name="panda_link6">
    <visual>
      <geometry>
        <mesh filename="package://franka_description/meshes/visual/link6.dae" />
      </geometry>
    </visual>
    <collision>
      <geometry>
        <mesh filename="package://franka_description/meshes/collision/link6.stl" />
      </geometry>
    </collision>
  </link>
  
  <link name="panda_link6_sc">
    <collision>
      <origin rpy="0 0 0" xyz="0 0 -0.03" />
      <geometry>
        <cylinder length="0.08" radius="0.08" />
      </geometry>
    </collision>
    <collision>
      <origin xyz="0 0 0.010000000000000002" />
      <geometry>
        <sphere radius="0.08" />
      </geometry>
    </collision>
    <collision>
      <origin xyz="0 0 -0.07" />
      <geometry>
        <sphere radius="0.08" />
      </geometry>
    </collision>
  </link>
  
  <joint name="panda_link6_sc_joint" type="fixed">
    <origin rpy="0 0 0" />
    <parent link="panda_link6" />
    <child link="panda_link6_sc" />
  </joint>
  <joint name="panda_joint6" type="revolute">
    <origin rpy="1.5720232741058109 0.0005556844933160503 0.005694638729896513" xyz="0.0007127391949080696 0.00030073005130449627 -0.0005943891456318758" />
    <parent link="panda_link5" />
    <child link="panda_link6" />
    <axis xyz="0 0 1" />
    <limit effort="12.0" lower="-0.0175" upper="3.7525" velocity="2.61" />
    <safety_controller k_position="100.0" k_velocity="40.0" soft_lower_limit="-0.0175" soft_upper_limit="3.7525" />
    <dynamics D="1" K="7000" damping="0.003" friction="0.0" mu_coulomb="0" mu_viscous="16" />
  </joint>
  
  <link name="panda_link7">
    <visual>
      <geometry>
        <mesh filename="package://franka_description/meshes/visual/link7.dae" />
      </geometry>
    </visual>
    <collision>
      <geometry>
        <mesh filename="package://franka_description/meshes/collision/link7.stl" />
      </geometry>
    </collision>
  </link>
  
  <link name="panda_link7_sc">
    <collision>
      <origin rpy="0 0 0" xyz="0 0 0.01" />
      <geometry>
        <cylinder length="0.14" radius="0.07" />
      </geometry>
    </collision>
    <collision>
      <origin xyz="0 0 0.08" />
      <geometry>
        <sphere radius="0.07" />
      </geometry>
    </collision>
    <collision>
      <origin xyz="0 0 -0.060000000000000005" />
      <geometry>
        <sphere radius="0.07" />
      </geometry>
    </collision>
    <collision>
      <origin rpy="0 1.5707963267948966 0" xyz="0.06 0 0.082" />
      <geometry>
        <cylinder length="0.01" radius="0.06" />
      </geometry>
    </collision>
    <collision>
      <origin xyz="0.065 0 0.082" />
      <geometry>
        <sphere radius="0.06" />
      </geometry>
    </collision>
    <collision>
      <origin xyz="0.055 0 0.082" />
      <geometry>
        <sphere radius="0.06" />
      </geometry>
    </collision>
  </link>
  
  <joint name="panda_link7_sc_joint" type="fixed">
    <origin rpy="0 0 0.7853981633974483" />
    <parent link="panda_link7" />
    <child link="panda_link7_sc" />
  </joint>
  <joint name="panda_joint7" type="revolute">
    <origin rpy="1.5703799854533402 -1.360390199411339e-07 -0.00032263196956828496" xyz="0.09008118106813627 -0.00259304223142981 -0.000295911280479944" />
    <parent link="panda_link6" />
    <child link="panda_link7" />
    <axis xyz="0 0 1" />
    <limit effort="12.0" lower="-2.8973" upper="2.8973" velocity="2.61" />
    <safety_controller k_position="100.0" k_velocity="40.0" soft_lower_limit="-2.8973" soft_upper_limit="2.8973" />
    <dynamics D="1" K="7000" damping="0.003" friction="0.0" mu_coulomb="0" mu_viscous="16" />
  </joint>
  <link name="panda_link8" />
  <joint name="panda_joint8" type="fixed">
    <origin rpy="0 0 0" xyz="0 0 0.107" />
    <parent link="panda_link7" />
    <child link="panda_link8" />
  </joint>
  <joint name="panda_hand_joint" type="fixed">
    <parent link="panda_link8" />
    <child link="panda_hand" />
    <origin rpy="0 0 -0.7853981633974483" xyz="0 0 0" />
  </joint>
  
  <link name="panda_hand">
    <visual>
      <geometry>
        <mesh filename="package://franka_description/meshes/visual/hand.dae" />
      </geometry>
    </visual>
    <collision>
      <geometry>
        <mesh filename="package://franka_description/meshes/collision/hand.stl" />
      </geometry>
    </collision>
  </link>
  
  <link name="panda_hand_sc">
    <collision>
      <origin rpy="1.5707963267948966 0 0" xyz="0 0 0.04" />
      <geometry>
        <cylinder length="0.1" radius="0.07" />
      </geometry>
    </collision>
    <collision>
      <origin xyz="0 0.05 0.04" />
      <geometry>
        <sphere radius="0.07" />
      </geometry>
    </collision>
    <collision>
      <origin xyz="0 -0.05 0.04" />
      <geometry>
        <sphere radius="0.07" />
      </geometry>
    </collision>
    <collision>
      <origin rpy="1.5707963267948966 0 0" xyz="0 0 0.1" />
      <geometry>
        <cylinder length="0.1" radius="0.05" />
      </geometry>
    </collision>
    <collision>
      <origin xyz="0 0.05 0.1" />
      <geometry>
        <sphere radius="0.05" />
      </geometry>
    </collision>
    <collision>
      <origin xyz="0 -0.05 0.1" />
      <geometry>
        <sphere radius="0.05" />
      </geometry>
    </collision>
  </link>
  
  <joint name="panda_hand_sc_joint" type="fixed">
    <origin rpy="0 0 0" />
    <parent link="panda_hand" />
    <child link="panda_hand_sc" />
  </joint>
  
  <link name="panda_hand_tcp" />
  <joint name="panda_hand_tcp_joint" type="fixed">
    <origin rpy="0.0 0.0 0.0" xyz="0.0003609507208606793 0.00017059979976771745 0.13099237856829304" />
    
    <parent link="panda_hand" />
    <child link="panda_hand_tcp" />
  </joint>
</robot>
